Workbook
Name base: 'Revenue synergy'!$C$25:$I$25
Name best: 'Revenue synergy'!$C$24:$I$24
Name worst: 'Revenue synergy'!$C$26:$I$26

Sheet M&A Model
B1: Merger & Acquistion Model
B4: Key Assumptions | J4: Rational
B6: Financial inputs | G6: Date 26-04-2026
B8: Acquirer Company (Sun Pharma)
B10: Share price (26-04-26) | H10: 1620
B11: Share outstanding | H11: 240
B12: Net Income | H12: 11509
B13: Tax Rate | H13: 0.25 | J13: 1. effective tax rate 2026 approx
B14: Cost Of Debt | H14: ='Cost Of Debt Estimation'!E58 -> 0.074137294
B16: Target Company (organon & Co.)
B18: Share Price (26-04-26) | H18: =11.26*94.9 -> 1068.574 | J18: 2. share price of Organon 0n 26-04-206 was 11.26$ ,converted it into INR
B19: Share Outstanding (Cr.) | H19: 28.5 | J19: 3. Organon fully diluted share the figure Sun Pharma actually used to size the deal
B20: Net income | H20: =18.7*87.6 -> 1638.12 | J20: 3. $18.7 cr net income as on 31-12-25
B21: Tax rate | H21: 0.244 | J21: 4. Organon's own non-GAAP effective rate was 24.4%, which is probably the more useful number for a WACC-style calc
B24: Transaction Assumption
B26: Target Premium | H26: =14/6.9-1 -> 1.0289855 | J26: 5. unaffected share price (09-04-26) = $6.9 and Deal price (26-04-26) = $14
B27: Cash Consideration | H27: 1 | J27: 6. acquisition hapeens in all cash basis
B28: Stock Consideration | H28: -
B29: Debt Consideration | H29: -
B30: Pre-Tax synergies | H30: ='Revenue synergy'!E12 -> 555.2008
B31: Transaction fees | H31: ='Transaction fees'!G15 -> 549.04395
B34: Transaction Pro forma Assumptions
B36: purchase Price And Financing
B38: Purchase (Deal) Price Per Share | H38: =14*E69 -> 1328.6 | J38: 7. $14 is a deal price which covert into INR using spot rate
B39: Total Equity Value (Purchase Price) | H39: =399*E69 -> 37865.1 | J39: 8. $399 Cr is equity value which convert in INR using spot rate
B40: Cash Required | H40: =H39 -> 37865.1
B41: Stock Required | H41: -
B42: Debt Required | H42: -
B43: Total Consideration | H43: =SUM(H40:H42) -> 37865.1
B46: Pro Forma Net Income
B48: Acquirer Net Income | H48: =H12 -> 11509
B49: Target Net Income | H49: =H20 -> 1638.12
B50: Synergies After Tax | H50: =H30*(1-H13) -> 416.4006
B51: New Interest Expense After Tax | H51: =H14*(1-H13) -> 0.055602971
B52: Pro Forma Net Income | H52: =SUM(H48:H50)*(1-H51) -> 12809.349
B55: Pro Forma Share Outstanding
B57: Acquirer Share Outstanding | H57: =H11 -> 240
B58: New Share Issued | H58: -
B59: proforma Share Outstanding | H59: =SUM(H57:H58) -> 240
B65: NOTE
...

Sheet Revenue synergy
B1: Revenue Synergies
B6: Particulars | E6: =F6-1 -> 0 | F6: 1 | G6: =F6+1 -> 2 | H6: =G6+1 -> 3 | I6: =H6+1 -> 4
B8: Synergies % | E8: {=CHOOSE(D15,E17:I17,E18:I18,E19:I19)} -> 0.01 | F8: 0.01 | G8: 0.015 | H8: 0.0175 | I8: 0.02
B9: Target Forecasted revenue % | E9: {=CHOOSE(D22,E24:I24,E25:I25,E26:I26)} -> 0.018 | F9: 0.02 | G9: 0.021 | H9: 0.022 | I9: 0.024
B10: Target Forecasted revenue (in Cr) | E10: =616*'M&A Model'!E70 -> 55520.08 | F10: =E10*(1+F9) -> 56630.482 | G10: =F10*(1+G9) -> 57819.722 | H10: =G10*(1+H9) -> 59091.756 | I10: =H10*(1+I9) -> 60509.958
B12: Revenue synergies (in Cr) 1 | E12: =E10*E8 -> 555.2008 | F12: =F10*F8 -> 566.30482 | G12: =G10*G8 -> 867.29583 | H12: =H10*H8 -> 1034.1057 | I12: =I10*I8 -> 1210.1992
B15: Scenarios For Synergies % | C15: Best Case | D15: =MATCH(C15,B17:B19,0) -> 1 | E15: =E6 -> 0 | F15: =F6 -> 1 | G15: =G6 -> 2 | H15: =H6 -> 3 | I15: =I6 -> 4
B17: Best Case | E17: 0.01 | F17: 0.01 | G17: 0.015 | H17: 0.0175 | I17: 0.02
B18: Base Case | E18: 0.005 | F18: 0.005 | G18: 0.01 | H18: 0.015 | I18: 0.02
B19: Worst Case | E19: 0.004 | F19: 0.005 | G19: 0.00075 | H19: 0.01 | I19: 0.0115
B22: Scenarios For Target Forecasted revenue % | C22: Worst Case | D22: =MATCH(C22,B24:B26,0) -> 3 | E22: =E15 -> 0 | F22: =F15 -> 1 | G22: =G15 -> 2 | H22: =H15 -> 3 | I22: =I15 -> 4
B24: =B17 -> Best Case | E24: 0.025 | F24: 0.027 | G24: 0.029 | H24: 0.031 | I24: 0.033
B25: =B18 -> Base Case | E25: 0.023 | F25: 0.023 | G25: 0.025 | H25: 0.027 | I25: 0.029
B26: =B19 -> Worst Case | E26: 0.018 | F26: 0.02 | G26: 0.021 | H26: 0.022 | I26: 0.024
B29: NOTE
B31: 1. Revenue synergies = target company's forecasted revenue * synergies %
B32: 2. historical CAGR for Organons revenue is 2.3 % based on past 3 years
B33: 3. trailing 12 month revenue of organon is $616 Cr. And multiplying $616 Cr from average rate we get revenue in INR

Sheet Cost Of Debt Estimation
B2: Pro-Forma Cost Of Debt Estimation
B6: 1) Sun Pharma (Consolidated) — Existing Debt Structure
B7: Source: Sun Pharma Annual Report FY2024-25 (audited financials) + FY26 interim disclosures
B9: Period | C9: Total Borrowings (INR) | E9: Finance Cost/Interest | F9: Implied Cost of Debt
B11: FY2025 (year ended Mar-25) | C11: 2362 | E11: 231 | F11: =E11/C11 -> 0.097798476
B12: FY2026 (year ended Mar-26) | C12: 4627 | E12: 339 | F12: =E12/C12 -> 0.073265615
B14: Average rate | F14: =SUMPRODUCT(F11:F12,C11:C12/SUM(C11:C12)) -> 0.081556732
B18: 2) Organon (Target) — Existing Debt Structure
B19: Source: Organon & Co. Form 10-K, FY2025 (filed with SEC, period ended Dec 31, 2025)
B21: Instrument | C21: Total Borrowings (USD) | E21: Rate | F21: Due Date
B23: USD Term Loan B (Senior Credit Agreement) | C23: 154.3 | E23: 0.0589 | F23: SOFR (3.64%) + 225bps, due 2031
B24: EUR Term Loan B | C24: 84.3 | E24: 0.0492 | F24: EURIBOR (2.17%) + 275bps, due 2031
B25: secured notes | C25: 210 | E25: 0.04125 | F25: Fixed, due 2028
B26: euro secured notes | C26: 147 | E26: 0.02875 | F26: Fixed, due 2028
B27: notes | C27: 158.2 | E27: 0.05125 | F27: Fixed, due 2031
B28: secured notes | C28: 50 | E28: 0.0675 | F28: Fixed, due 2034
B29: notes | C29: 50 | E29: 0.07875 | F29: Fixed, due 2034
B30: Others | C30: 10
B31: Total principal debt | C31: =SUM(C23:C30) -> 863.8 | E31: =SUMPRODUCT(E23:E29,C23:C29/SUM(C23:C29)) -> 0.048658737
B35: 3) Sun Pharma (Consolidated) — New Debt Issued
B36: No publicaly Data Available
B38: Debt Type | C38: Total Borrowings (USD) | E38: Rate Used in Model | F38: Range
B40: Bridge Loan | C40: 300 | E40: 0.062 | F40: 6.0–6.5%
B41: Term Loan A | C41: 250 | E41: 0.06 | F41: 5.8–6.2%
B42: Term Loan B | C42: 300 | E42: 0.064 | F42: 6.2–6.8%
B43: Revolving Credit Facility | C43: 125 | E43: 0.06 | F43: 5.8-6.2 (depending on SOFAR)
B45: Total | C45: =SUM(C40:C43) -> 975 | E45: =AVERAGE(E40:E43) -> 0.0615
B50: Pro-Froma Cost Of Debt
B52: Debt Category | C52: Total Borrowings | E52: Interest Rate
B54: Exisiting Sun Pharma Debt (INR) | C54: =C12 -> 4627 | E54: =F14 -> 0.081556732
B55: Exsisting Organon Co. Debt (USD) | C55: =C31 -> 863.8 | E55: =E31 -> 0.048658737
B56: New Debt issued by Sun Pharma (USD) | C56: =C45 -> 975 | E56: =E45 -> 0.0615
B58: Total Cost Of Debt | E58: =SUMPRODUCT(C54:C56,E54:E56/SUM(C54:C56)) -> 0.074137294
B64: NOTES
B66: SOFAR Rate on 26-04-2026 - 3.64 (source - global rates .com)
B67: EURIBOR Rate on 26-04-2026 - 2.17 (source - euribor rates .com)

Sheet Transaction fees
B2: Transaction Fees Assumptions
B6: Fee Type | C6: Typical Range | G6: Average Rate
B8: Financial Advisory | C8: 0.3%-1.0% of equity value | G8: 0.0065
B9: Legal And Accounting | C9: 0.1%-0.3% of equity Value | G9: 0.004
B10: Financial Fees | C10: 0.2%-0.6% of debt issued | G10: 0.004
B12: Total Transaction Fees (in %) | C12: ~ 1.0%-2.0% of equity value | G12: 0.0145
B15: Total Transaction Fees (in amount) 1 | G15: ='M&A Model'!H39*G12 -> 549.04395
B18: NOTE
B20: 1. Transaction fees (amt) = equity Value * 1.5%
B21: 2. there is no publicaly avilable info on transaction fees

Sheet Accretion Dilution Analysis
B1: Accretion/Dilution Analysis
B4: Paticulars
B6: Acquirer EPS (StandAlone) | H6: ='M&A Model'!H12/'M&A Model'!H11 -> 47.954167
B7: Proforma EPS | H7: ='M&A Model'!H52/'M&A Model'!H59 -> 53.372286
B8: Accertion/Dilution | H8: =H7/H6-1 -> 0.11298536
B11: Key findings
B13: ● Pro forma EPS is 9.59% higher than standalone EPS, suggesting that merger synergies and financing assumptions outweigh acquisition-related costs.
B14: ● A positive EPS accretion of 9.59% implies the acquisition is expected to enhance shareholder earnings and is financially attractive.
